<?xml version="1.0" ?>
<sdf version="1.6">
	<model name='jeep'>
		<pose>0 0 0 0 0 3.1415926</pose>
		<link name='frame_link'>
			<pose>0 0 0 0 0 0</pose>
			<velocity_decay>
		    	<linear>0.0</linear>
		    	<angular>0.0</angular>
			</velocity_decay>
			<inertial>
				<pose>0 0 0 0 0 0</pose>
				<mass>15</mass>
				<inertia>
				  <ixx>4</ixx>
				  <ixy>0</ixy>
				  <ixz>0</ixz>
				  <iyy>4</iyy>
				  <iyz>0</iyz>
				  <izz>5</izz>
				</inertia>
			</inertial>
			<collision name="collision_frame">
				<geometry>
					<mesh>
						<uri>model://jeep/mesh/frame/frame.dae</uri>
					</mesh>
				</geometry>
			</collision>
			<visual name='frame_visual'>
				<geometry>
					<mesh>
						<uri>model://jeep/mesh//frame/frame.dae</uri>
					</mesh>
				</geometry>
			</visual>
		</link>
	<!-- left front wheel-->
		<link name='tire_left_front_link'>
		<pose>-1.19 -0.57 -0.57 0 0 0</pose>
		<collision name="collision_tire_left_front">
			<geometry>
				<mesh>
					<uri>model://jeep/mesh/tire/tire.dae</uri>
				</mesh>
			</geometry>
			<surface>
		      <friction>
		        <ode>
		          <mu>0.5</mu>
		          <mu2>0.5</mu2>
		        </ode>
		      </friction>
			</surface>
		</collision>
		<visual name='tire_left_front_visual'>
			<geometry>
				<mesh>
					<uri>model://jeep/mesh/tire/tire.dae</uri>
					</mesh>
			</geometry>
		</visual>
		</link>
	<!-- right front wheel -->
		<link name='tire_right_front_link'>
		<pose>-1.19 0.75 -0.57 0 0 3.1415926</pose>
		<collision name="collision_tire_right_front">
			<geometry>
				<mesh>
					<uri>model://jeep/mesh/tire/tire.dae</uri>
				</mesh>
			</geometry>
			<surface>
		      <friction>
		        <ode>
		          <mu>0.5</mu>
		          <mu2>0.5</mu2>
		        </ode>
		      </friction>
			</surface>
		</collision>
		<visual name='tire_right_front_visual'>
			<geometry>
				<mesh>
					<uri>model://jeep/mesh/tire/tire.dae</uri>
				</mesh>
			</geometry>
		</visual>
		</link>
		
		<!-- left back wheel-->
		<link name='tire_left_back_link'>
		<pose>0.95 -0.57 -0.57 0 0 0</pose>
		<collision name="collision_tire_left_back">
			<geometry>
				<mesh>
					<uri>model://jeep/mesh/tire/tire.dae</uri>
				</mesh>
			</geometry>
			<surface>
		      <friction>
		        <ode>
		          <mu>0.5</mu>
		          <mu2>0.5</mu2>
		        </ode>
		      </friction>
			</surface>
		</collision>
		<visual name='tire_left_back_visual'>
			<geometry>
				<mesh>
					<uri>model://jeep/mesh/tire/tire.dae</uri>
					</mesh>
			</geometry>
		</visual>
		</link>
		<joint name='left_back_jiont' type='revolute'>
			<child>tire_left_back_link</child>
			<parent>frame_link</parent>
			<axis>
		    	<xyz>0 -1 0</xyz>
				<limit>
		      		<lower>-1e+16</lower>
		      		<upper>1e+16</upper>
		    	</limit>
		    	<dynamics>
		      		<damping>0.04</damping>
					<friction>5</friction>
		    	</dynamics>
		    	<use_parent_model_frame>1</use_parent_model_frame>
			</axis>
		</joint>
		<!-- right back wheel-->
		<link name='tire_right_back_link'>
		<pose>0.95 0.75 -0.57 0 0 3.1415926</pose>
		<collision name="collision_tire_right_back">
			<geometry>
				<mesh>
					<uri>model://jeep/mesh/tire/tire.dae</uri>
				</mesh>
			</geometry>
			<surface>
		      <friction>
		        <ode>
		          <mu>0.5</mu>
		          <mu2>0.5</mu2>
		        </ode>
		      </friction>
			</surface>
		</collision>
		<visual name='tire_right_back_visual'>
			<geometry>
				<mesh>
					<uri>model://jeep/mesh/tire/tire.dae</uri>
					</mesh>
			</geometry>
		</visual>
		</link>
		<joint name='right_back_jiont' type='revolute'>
			<child>tire_right_back_link</child>
			<parent>frame_link</parent>
			<axis>
		    	<xyz>0 -1 0</xyz>
				<limit>
		      		<lower>-1e+16</lower>
		      		<upper>1e+16</upper>
		    	</limit>
		    	<dynamics>
		      		<damping>0.004</damping>
					<friction>5</friction>
		    	</dynamics>
		    	<use_parent_model_frame>1</use_parent_model_frame>
			</axis>
		</joint>
	<!--front wheel steer-->
		<joint name='left_front_steer_jiont' type='universal'>
			<child>tire_left_front_link</child>
			<parent>frame_link</parent>
			<axis>
		    	<xyz>0 0 -1</xyz>
				<limit>
		      		<lower>-0.785398</lower>
		      		<upper>0.785398</upper>
		    	</limit>
		    	<dynamics>
		      		<damping>0.004</damping>
					<friction>0.05</friction>
		    	</dynamics>
		    	<use_parent_model_frame>1</use_parent_model_frame>
			</axis>
			<axis2>
				<xyz>0 1 0</xyz>
				<limit>
		      		<lower>-1e+16</lower>
		      		<upper>1e+16</upper>
		    	</limit>
		    	<dynamics>
		      		<damping>0.004</damping>
					<friction>5</friction>
		    	</dynamics>
		    	<use_parent_model_frame>1</use_parent_model_frame>
			</axis2>
		</joint>
		<joint name='right_front_steer_jiont' type='universal'>
			<child>tire_right_front_link</child>
			<parent>frame_link</parent>
			<axis>
		    	<xyz>0 0 -1</xyz>
				<limit>
		      		<lower>-0.785398</lower>
		      		<upper>0.785398</upper>
		    	</limit>
		    	<dynamics>
		      		<damping>0.004</damping>
					<friction>0.05</friction>
		    	</dynamics>
		    	<use_parent_model_frame>1</use_parent_model_frame>
			</axis>
			<axis2>
				<xyz>0 1 0</xyz>
				<limit>
		      		<lower>-1e+16</lower>
		      		<upper>1e+16</upper>
		    	</limit>
		    	<dynamics>
		      		<damping>0.004</damping>
					<friction>5</friction>
		    	</dynamics>
		    	<use_parent_model_frame>1</use_parent_model_frame>
			</axis2>
		</joint>
		
	<!-- IMU-->
		<link name='jeep_imu_link'>
		  <inertial>
		    <pose>0 0 0 0 0 0</pose>
		    <mass>0.15</mass>
		    <inertia>
		      <ixx>0.00001</ixx>
		      <ixy>0</ixy>
		      <ixz>0</ixz>
		      <iyy>0.00002</iyy>
		      <iyz>0</iyz>
		      <izz>0.00002</izz>
		    </inertia>
		  </inertial>
		  <sensor name="jeep_imu_sensor" type="imu">
		    <pose>0 0 0 3.141593 0 3.141593</pose>
		    <always_on>1</always_on>
		    <update_rate>1000.0</update_rate>
		  </sensor>
		</link>
		<joint name='jeep_imu_joint' type='revolute'>
		  <child>jeep_imu_link</child>
		  <parent>frame_link</parent>
		  <axis>
		    <xyz>0 0 1</xyz>
		    <limit>
		      <lower>0</lower>
		      <upper>0</upper>
		      <effort>0</effort>
		      <velocity>0</velocity>
		    </limit>
		    <dynamics>
		      <damping>1.0</damping>
		    </dynamics>
		    <use_parent_model_frame>1</use_parent_model_frame>
		  </axis>
		  <physics>
		    <ode>
		      <implicit_spring_damper>1</implicit_spring_damper>
		    </ode>
		  </physics>
		</joint>
	</model>
</sdf>
